Workbook

Sheet GANTT progetto
C3: 2026 | D3: 2027 | E3: 2028 | F3: 2029 | G3: 2030 | H3: 2031
B4: Fase 1: Sviluppo
B5: Fase 2: Esercizio

Sheet Plan Fase 1
C4: TASK / SUBTASK | D4: 1 | F4: 2 | H4: 3 | J4: 4 | L4: 5 | N4: 6 | P4: 7 | R4: 8 | T4: 9 | V4: 10 | X4: 11 | Z4: 12
C5: A Organizzazione Progetto
C6: A1 Set-Up del Progetto
C7: A2 Gruppi e Ambienti di sviluppo
C8: B Sottosistema Back-End
C9: B1 Gestione dei Database
C10: B2 Modulo Intelligenza Artificiale
C11: B3 Modulo Gestione Transazioni
C12: B4 Modulo Operazioni Applicativi
C13: B5 Modulo Raccolta Feedback
C14: C Sottosistema Produttore
C15: C1 Modulo di Accesso
C16: C2 Modulo Registrazione Prodotti
... C32: G2 Deployment
A34: OP Anno | B34: 1752
A35: OP Mese | B35: =B34/12 -> 146
A36: OP 15 giorni | B36: =B35/2 -> 73
C38: 1 PM | D38: 1 | F38: 2 | H38: 3 | J38: 4 | L38: 5 | N38: 6 | P38: 7 | R38: 8 | T38: 9 | V38: 10 | X38: 11 | Z38: 12 | AB38: O/P
C39: A Organizzazione Progetto | AB39: =SUM(AB40:AB41) -> 146
C40: A1 Set-Up del Progetto | D40: 1 | AB40: =SUM(D40:AA40)*$B$35/2 -> 73
C41: A2 Gruppi e Ambienti di sviluppo | E41: 1 | AB41: =SUM(D41:AA41)*$B$35/2 -> 73
C42: B Sottosistema Back-End | AB42: =SUM(AB43:AB47) -> 525.6
C43: B1 Gestione dei Database | F43: 0.4 | G43: 0.4 | AB43: =SUM(D43:AA43)*$B$35/2 -> 58.4
C44: B2 Modulo Intelligenza Artificiale | H44: 0.4 | I44: 0.4 | J44: 0.4 | K44: 0.4 | AB44: =SUM(D44:AA44)*$B$35/2 -> 116.8
C45: B3 Modulo Gestione Transazioni | L45: 0.4 | M45: 0.4 | N45: 0.4 | O45: 0.4 | P45: 0.4 | Q45: 0.4 | AB45: =SUM(D45:AA45)*$B$35/2 -> 175.2
C46: B4 Modulo Operazioni Applicativi | R46: 0.4 | S46: 0.4 | T46: 0.4 | U46: 0.4 | AB46: =SUM(D46:AA46)*$B$35/2 -> 116.8
C47: B5 Modulo Raccolta Feedback | V47: 0.4 | W47: 0.4 | AB47: =SUM(D47:AA47)*$B$35/2 -> 58.4
C48: C Sottosistema Produttore | AB48: =SUM(AB49:AB52) -> 240.9
C49: C1 Modulo di Accesso | F49: 0.3 | AB49: =SUM(D49:AA49)*$B$35/2 -> 21.9
C50: C2 Modulo Registrazione Prodotti | G50: 0.3 | H50: 0.3 | I50: 0.3 | J50: 0.3 | K50: 0.3 | AB50: =SUM(D50:AA50)*$B$35/2 -> 109.5
C51: C3 Modulo Gestione Dati Prodotti | L51: 0.3 | M51: 0.3 | N51: 0.3 | O51: 0.3 | AB51: =SUM(D51:AA51)*$B$35/2 -> 87.6
C52: C4 Modulo Invio Feedback | P52: 0.3 | AB52: =SUM(D52:AA52)*$B$35/2 -> 21.9
C53: D Sottosistema Riparazioni e Certificazioni | AB53: =SUM(AB54:AB56) -> 153.3
C54: D1 Modulo di Accesso | Q54: 0.3 | AB54: =SUM(D54:AA54)*$B$35/2 -> 21.9
C55: D2 Modulo Riparazioni | R55: 0.3 | S55: 0.3 | T55: 0.3 | AB55: =SUM(D55:AA55)*$B$35/2 -> 65.7
C56: D3 Modulo Certificazioni | U56: 0.3 | V56: 0.3 | W56: 0.3 | AB56: =SUM(D56:AA56)*$B$35/2 -> 65.7
C57: E Sottosistema Front-End | AB57: =SUM(AB58:AB60) -> 306.6
C58: E1 Modulo di Accesso | F58: 0.3 | G58: 0.3 | AB58: =SUM(D58:AA58)*$B$35/2 -> 43.8
C59: E2 Modulo Acquisto | H59: 0.3 | I59: 0.3 | J59: 0.3 | K59: 0.3 | L59: 0.3 | M59: 0.3 | AB59: =SUM(D59:AA59)*$B$35/2 -> 131.4
C60: E3 Modulo Vendita | N60: 0.3 | O60: 0.3 | P60: 0.3 | Q60: 0.3 | R60: 0.3 | S60: 0.3 | AB60: =SUM(D60:AA60)*$B$35/2 -> 131.4
...

Sheet Gruppi Fase 1
B3: Gruppo | C3: Num Persone | D3: Tipologia | E3: Tasks | F3: O/P | G3: A/P
B4: 0 | C4: 14 | D4: 1 PM 1 SA 4 FSD 8 FSDJ | E4: A Organizzazione Progetto G Integrazione/Testing complessivo e Deployment | F4: =SUMIF('Plan Fase 1'!B$165:B$192,'Gruppi Fase 1'!B4,'Plan Fase 1'!AB$165:AB$192) -> 5548 | G4: =F4/'Plan Fase 1'!B$34 -> 3.1666667
B5: 1 | C5: 4.9 | D5: 0,40 PM 0,50 SA 2 FSD 2 FSDJ | E5: B Sottosistema Back-End | F5: =SUMIF('Plan Fase 1'!B$165:B$192,'Gruppi Fase 1'!B5,'Plan Fase 1'!AB$165:AB$192) -> 6438.6 | G5: =F5/'Plan Fase 1'!B$34 -> 3.675
B6: 2 | C6: 4.55 | D6: 0,3 PM 0,25 SA 1 FSD 3 FSDJ | E6: C Sottosistema Produttore D Sottosistema Riparazioni e Certificazioni | F6: =SUMIF('Plan Fase 1'!B$165:B$192,'Gruppi Fase 1'!B6,'Plan Fase 1'!AB$165:AB$192) -> 5978.7 | G6: =F6/'Plan Fase 1'!B$34 -> 3.4125
B7: 3 | C7: 4.55 | D7: 0,3 PM 0,25 SA 1 FSD 3 FSDJ | E7: E Sottosistema Front-End F Sottosistema Intermediario | F7: =SUMIF('Plan Fase 1'!B$165:B$192,'Gruppi Fase 1'!B7,'Plan Fase 1'!AB$165:AB$192) -> 5978.7 | G7: =F7/'Plan Fase 1'!B$34 -> 3.4125
B8: TOTALE | C8: 14 | D8: 1 PM 1 SA 4 FSD 8 FSDJ | E8: A Organizzazione Progetto B Sottosistema Back-End C Sottosistema Produttore D Sottosistema Riparazioni e Certificazioni E Sottosistema Front-End F Sottosistema Intermediario G Integrazione/Testing complessivo e Deployment | F8: =SUM(F4:F7) -> 23944 | G8: =F8/'Plan Fase 1'!B$34 -> 13.666667

Sheet Plan Fase 2
D3: ANNO 1 | H3: ANNO 2 | L3: ANNO 3 | P3: ANNO 4 | T3: ANNO 5
C4: TASK / SUBTASK | D4: SEM 1 | F4: SEM 2 | H4: SEM 1 | J4: SEM 2 | L4: SEM 1 | N4: SEM 2 | P4: SEM 1 | R4: SEM 2 | T4: SEM 1 | V4: SEM 2
C5: A. Promozione Piattaforma e Assistenza Commerciale
C6: B. Manutenzione Ordinaria
C7: C. Manutenzione Evolutiva
C8: D. Assistenza Intermediari
C9: E. Analisi di Dati di Esercizio della piattaforma
A11: OP Anno | B11: ='Plan Fase 1'!B34 -> 1752
A12: OP TRIMESTRE | B12: =B11/4 -> 438
D15: ANNO 1 | H15: ANNO 2 | L15: ANNO 3 | P15: ANNO 4 | T15: ANNO 5 | X15: O/P
C16: 1 PM | D16: SEM 1 | F16: SEM 2 | H16: SEM 1 | J16: SEM 2 | L16: SEM 1 | N16: SEM 2 | P16: SEM 1 | R16: SEM 2 | T16: SEM 1 | V16: SEM 2 | X16: ANNO 1 | Y16: ANNO 2 | Z16: ANNO 3 | AA16: ANNO 4 | AB16: ANNO 5 | AC16: TOTALE
C17: A. Promozione Piattaforma e Assistenza Commerciale | D17: 0.25 | E17: 0.25 | F17: 0.25 | G17: 0.25 | H17: 0.25 | I17: 0.25 | J17: 0.25 | K17: 0.25 | L17: 0.2 | M17: 0.2 | N17: 0.2 | O17: 0.2 | P17: 0.2 | Q17: 0.2 | R17: 0.2 | S17: 0.2 | T17: 0.2 | U17: 0.2 | V17: 0.2 | W17: 0.2 | X17: =SUM(D17:G17)*$B$12 -> 438 | Y17: =SUM(H17:K17)*$B$12 -> 438 | Z17: =SUM(L17:O17)*$B$12 -> 350.4 | AA17: =SUM(P17:S17)*$B$12 -> 350.4 | AB17: =SUM(T17:W17)*$B$12 -> 350.4 | AC17: =SUM(X17:AB17) -> 1927.2
C18: B. Manutenzione Ordinaria | D18: 0.1 | E18: 0.1 | F18: 0.1 | G18: 0.1 | H18: 0.1 | I18: 0.1 | J18: 0.1 | K18: 0.1 | L18: 0.05 | M18: 0.05 | N18: 0.05 | O18: 0.05 | P18: 0.05 | Q18: 0.05 | R18: 0.05 | S18: 0.05 | T18: 0.05 | U18: 0.05 | V18: 0.05 | W18: 0.05 | X18: =SUM(D18:G18)*$B$12 -> 175.2 | Y18: =SUM(H18:K18)*$B$12 -> 175.2 | Z18: =SUM(L18:O18)*$B$12 -> 87.6 | AA18: =SUM(P18:S18)*$B$12 -> 87.6 | AB18: =SUM(T18:W18)*$B$12 -> 87.6 | AC18: =SUM(X18:AB18) -> 613.2
C19: C. Manutenzione Evolutiva | L19: 0.15 | M19: 0.15 | N19: 0.15 | O19: 0.15 | P19: 0.15 | Q19: 0.15 | R19: 0.15 | S19: 0.15 | T19: 0.15 | U19: 0.15 | V19: 0.15 | W19: 0.15 | X19: =SUM(D19:G19)*$B$12 -> 0 | Y19: =SUM(H19:K19)*$B$12 -> 0 | Z19: =SUM(L19:O19)*$B$12 -> 262.8 | AA19: =SUM(P19:S19)*$B$12 -> 262.8 | AB19: =SUM(T19:W19)*$B$12 -> 262.8 | AC19: =SUM(X19:AB19) -> 788.4
C20: D. Assistenza Intermediari | D20: 0.1 | E20: 0.1 | F20: 0.1 | G20: 0.1 | H20: 0.1 | I20: 0.1 | J20: 0.1 | K20: 0.1 | L20: 0.05 | M20: 0.05 | N20: 0.05 | O20: 0.05 | P20: 0.05 | Q20: 0.05 | R20: 0.05 | S20: 0.05 | T20: 0.05 | U20: 0.05 | V20: 0.05 | W20: 0.05 | X20: =SUM(D20:G20)*$B$12 -> 175.2 | Y20: =SUM(H20:K20)*$B$12 -> 175.2 | Z20: =SUM(L20:O20)*$B$12 -> 87.6 | AA20: =SUM(P20:S20)*$B$12 -> 87.6 | AB20: =SUM(T20:W20)*$B$12 -> 87.6 | AC20: =SUM(X20:AB20) -> 613.2
C21: E. Analisi di Dati di Esercizio della piattaforma | D21: 0.05 | E21: 0.05 | F21: 0.05 | G21: 0.05 | H21: 0.05 | I21: 0.05 | J21: 0.05 | K21: 0.05 | L21: 0.05 | M21: 0.05 | N21: 0.05 | O21: 0.05 | P21: 0.05 | Q21: 0.05 | R21: 0.05 | S21: 0.05 | T21: 0.05 | U21: 0.05 | V21: 0.05 | W21: 0.05 | X21: =SUM(D21:G21)*$B$12 -> 87.6 | Y21: =SUM(H21:K21)*$B$12 -> 87.6 | Z21: =SUM(L21:O21)*$B$12 -> 87.6 | AA21: =SUM(P21:S21)*$B$12 -> 87.6 | AB21: =SUM(T21:W21)*$B$12 -> 87.6 | AC21: =SUM(X21:AB21) -> 438
C22: TOTALE | D22: =SUM(D17:D21) -> 0.5 | E22: =SUM(E17:E21) -> 0.5 | F22: =SUM(F17:F21) -> 0.5 | G22: =SUM(G17:G21) -> 0.5 | H22: =SUM(H17:H21) -> 0.5 | I22: =SUM(I17:I21) -> 0.5 | J22: =SUM(J17:J21) -> 0.5 | K22: =SUM(K17:K21) -> 0.5 | ... AB22: =SUM(AB17:AB21) -> 876 | AC22: =SUM(X22:AB22) -> 4380
D24: ANNO 1 | H24: ANNO 2 | L24: ANNO 3 | P24: ANNO 4 | T24: ANNO 5 | X24: O/P
C25: 1 SA | D25: SEM 1 | F25: SEM 2 | H25: SEM 1 | J25: SEM 2 | L25: SEM 1 | N25: SEM 2 | P25: SEM 1 | R25: SEM 2 | T25: SEM 1 | V25: SEM 2 | X25: ANNO 1 | Y25: ANNO 2 | Z25: ANNO 3 | AA25: ANNO 4 | AB25: ANNO 5 | AC25: TOTALE
C26: A. Promozione Piattaforma e Assistenza Commerciale | D26: 0.15 | E26: 0.15 | F26: 0.15 | G26: 0.15 | H26: 0.15 | I26: 0.15 | J26: 0.15 | K26: 0.15 | L26: 0.1 | M26: 0.1 | N26: 0.1 | O26: 0.1 | P26: 0.1 | Q26: 0.1 | R26: 0.1 | S26: 0.1 | T26: 0.1 | U26: 0.1 | V26: 0.1 | W26: 0.1 | X26: =SUM(D26:G26)*$B$12 -> 262.8 | Y26: =SUM(H26:K26)*$B$12 -> 262.8 | Z26: =SUM(L26:O26)*$B$12 -> 175.2 | AA26: =SUM(P26:S26)*$B$12 -> 175.2 | AB26: =SUM(T26:W26)*$B$12 -> 175.2 | AC26: =SUM(X26:AB26) -> 1051.2
C27: B. Manutenzione Ordinaria | D27: 0.1 | E27: 0.1 | F27: 0.1 | G27: 0.1 | H27: 0.1 | I27: 0.1 | J27: 0.1 | K27: 0.1 | L27: 0.05 | M27: 0.05 | N27: 0.05 | O27: 0.05 | P27: 0.05 | Q27: 0.05 | R27: 0.05 | S27: 0.05 | T27: 0.05 | U27: 0.05 | V27: 0.05 | W27: 0.05 | X27: =SUM(D27:G27)*$B$12 -> 175.2 | Y27: =SUM(H27:K27)*$B$12 -> 175.2 | Z27: =SUM(L27:O27)*$B$12 -> 87.6 | AA27: =SUM(P27:S27)*$B$12 -> 87.6 | AB27: =SUM(T27:W27)*$B$12 -> 87.6 | AC27: =SUM(X27:AB27) -> 613.2
C28: C. Manutenzione Evolutiva | L28: 0.2 | M28: 0.2 | N28: 0.2 | O28: 0.2 | P28: 0.2 | Q28: 0.2 | R28: 0.2 | S28: 0.2 | T28: 0.2 | U28: 0.2 | V28: 0.2 | W28: 0.2 | X28: =SUM(D28:G28)*$B$12 -> 0 | Y28: =SUM(H28:K28)*$B$12 -> 0 | Z28: =SUM(L28:O28)*$B$12 -> 350.4 | AA28: =SUM(P28:S28)*$B$12 -> 350.4 | AB28: =SUM(T28:W28)*$B$12 -> 350.4 | AC28: =SUM(X28:AB28) -> 1051.2
C29: D. Assistenza Intermediari | D29: 0.15 | E29: 0.15 | F29: 0.15 | G29: 0.15 | H29: 0.15 | I29: 0.15 | J29: 0.15 | K29: 0.15 | L29: 0.05 | M29: 0.05 | N29: 0.05 | O29: 0.05 | P29: 0.05 | Q29: 0.05 | R29: 0.05 | S29: 0.05 | T29: 0.05 | U29: 0.05 | V29: 0.05 | W29: 0.05 | X29: =SUM(D29:G29)*$B$12 -> 262.8 | Y29: =SUM(H29:K29)*$B$12 -> 262.8 | Z29: =SUM(L29:O29)*$B$12 -> 87.6 | AA29: =SUM(P29:S29)*$B$12 -> 87.6 | AB29: =SUM(T29:W29)*$B$12 -> 87.6 | AC29: =SUM(X29:AB29) -> 788.4
C30: E. Analisi di Dati di Esercizio della piattaforma | D30: 0.1 | E30: 0.1 | F30: 0.1 | G30: 0.1 | H30: 0.1 | I30: 0.1 | J30: 0.1 | K30: 0.1 | L30: 0.1 | M30: 0.1 | N30: 0.1 | O30: 0.1 | P30: 0.1 | Q30: 0.1 | R30: 0.1 | S30: 0.1 | T30: 0.1 | U30: 0.1 | V30: 0.1 | W30: 0.1 | X30: =SUM(D30:G30)*$B$12 -> 175.2 | Y30: =SUM(H30:K30)*$B$12 -> 175.2 | Z30: =SUM(L30:O30)*$B$12 -> 175.2 | AA30: =SUM(P30:S30)*$B$12 -> 175.2 | AB30: =SUM(T30:W30)*$B$12 -> 175.2 | AC30: =SUM(X30:AB30) -> 876
C31: TOTALE | D31: =SUM(D26:D30) -> 0.5 | E31: =SUM(E26:E30) -> 0.5 | F31: =SUM(F26:F30) -> 0.5 | G31: =SUM(G26:G30) -> 0.5 | H31: =SUM(H26:H30) -> 0.5 | I31: =SUM(I26:I30) -> 0.5 | J31: =SUM(J26:J30) -> 0.5 | K31: =SUM(K26:K30) -> 0.5 | ... AB31: =SUM(AB26:AB30) -> 876 | AC31: =SUM(X31:AB31) -> 4380
D33: ANNO 1 | H33: ANNO 2 | L33: ANNO 3 | P33: ANNO 4 | T33: ANNO 5 | X33: O/P
C34: 2 FSD | D34: SEM 1 | F34: SEM 2 | H34: SEM 1 | J34: SEM 2 | L34: SEM 1 | N34: SEM 2 | P34: SEM 1 | R34: SEM 2 | T34: SEM 1 | V34: SEM 2 | X34: ANNO 1 | Y34: ANNO 2 | Z34: ANNO 3 | AA34: ANNO 4 | AB34: ANNO 5 | AC34: TOTALE
C35: A. Promozione Piattaforma e Assistenza Commerciale | D35: 0.2 | E35: 0.2 | F35: 0.2 | G35: 0.2 | H35: 0.2 | I35: 0.2 | J35: 0.2 | K35: 0.2 | L35: 0.1 | M35: 0.1 | N35: 0.1 | O35: 0.1 | P35: 0.1 | Q35: 0.1 | R35: 0.1 | S35: 0.1 | T35: 0.1 | U35: 0.1 | V35: 0.1 | W35: 0.1 | X35: =SUM(D35:G35)*$B$12 -> 350.4 | Y35: =SUM(H35:K35)*$B$12 -> 350.4 | Z35: =SUM(L35:O35)*$B$12 -> 175.2 | AA35: =SUM(P35:S35)*$B$12 -> 175.2 | AB35: =SUM(T35:W35)*$B$12 -> 175.2 | AC35: =SUM(X35:AB35) -> 1226.4
C36: B. Manutenzione Ordinaria | D36: 0.9 | E36: 0.9 | F36: 0.9 | G36: 0.9 | H36: 0.9 | I36: 0.9 | J36: 0.9 | K36: 0.9 | L36: 0.4 | M36: 0.4 | N36: 0.4 | O36: 0.4 | P36: 0.4 | Q36: 0.4 | R36: 0.4 | S36: 0.4 | T36: 0.4 | U36: 0.4 | V36: 0.4 | W36: 0.4 | X36: =SUM(D36:G36)*$B$12 -> 1576.8 | Y36: =SUM(H36:K36)*$B$12 -> 1576.8 | Z36: =SUM(L36:O36)*$B$12 -> 700.8 | AA36: =SUM(P36:S36)*$B$12 -> 700.8 | AB36: =SUM(T36:W36)*$B$12 -> 700.8 | AC36: =SUM(X36:AB36) -> 5256
C37: C. Manutenzione Evolutiva | L37: 0.8 | M37: 0.8 | N37: 0.8 | O37: 0.8 | P37: 0.8 | Q37: 0.8 | R37: 0.8 | S37: 0.8 | T37: 0.8 | U37: 0.8 | V37: 0.8 | W37: 0.8 | X37: =SUM(D37:G37)*$B$12 -> 0 | Y37: =SUM(H37:K37)*$B$12 -> 0 | Z37: =SUM(L37:O37)*$B$12 -> 1401.6 | AA37: =SUM(P37:S37)*$B$12 -> 1401.6 | AB37: =SUM(T37:W37)*$B$12 -> 1401.6 | AC37: =SUM(X37:AB37) -> 4204.8
C38: D. Assistenza Intermediari | D38: 0.5 | E38: 0.5 | F38: 0.5 | G38: 0.5 | H38: 0.5 | I38: 0.5 | J38: 0.5 | K38: 0.5 | L38: 0.3 | M38: 0.3 | N38: 0.3 | O38: 0.3 | P38: 0.3 | Q38: 0.3 | R38: 0.3 | S38: 0.3 | T38: 0.3 | U38: 0.3 | V38: 0.3 | W38: 0.3 | X38: =SUM(D38:G38)*$B$12 -> 876 | Y38: =SUM(H38:K38)*$B$12 -> 876 | Z38: =SUM(L38:O38)*$B$12 -> 525.6 | AA38: =SUM(P38:S38)*$B$12 -> 525.6 | AB38: =SUM(T38:W38)*$B$12 -> 525.6 | AC38: =SUM(X38:AB38) -> 3328.8
C39: E. Analisi di Dati di Esercizio della piattaforma | D39: 0.4 | E39: 0.4 | F39: 0.4 | G39: 0.4 | H39: 0.4 | I39: 0.4 | J39: 0.4 | K39: 0.4 | L39: 0.4 | M39: 0.4 | N39: 0.4 | O39: 0.4 | P39: 0.4 | Q39: 0.4 | R39: 0.4 | S39: 0.4 | T39: 0.4 | U39: 0.4 | V39: 0.4 | W39: 0.4 | X39: =SUM(D39:G39)*$B$12 -> 700.8 | Y39: =SUM(H39:K39)*$B$12 -> 700.8 | Z39: =SUM(L39:O39)*$B$12 -> 700.8 | AA39: =SUM(P39:S39)*$B$12 -> 700.8 | AB39: =SUM(T39:W39)*$B$12 -> 700.8 | AC39: =SUM(X39:AB39) -> 3504
C40: TOTALE | D40: =SUM(D35:D39) -> 2 | E40: =SUM(E35:E39) -> 2 | F40: =SUM(F35:F39) -> 2 | G40: =SUM(G35:G39) -> 2 | H40: =SUM(H35:H39) -> 2 | I40: =SUM(I35:I39) -> 2 | J40: =SUM(J35:J39) -> 2 | K40: =SUM(K35:K39) -> 2 | ... AB40: =SUM(AB35:AB39) -> 3504 | AC40: =SUM(X40:AB40) -> 17520
D42: ANNO 1 | H42: ANNO 2 | L42: ANNO 3 | P42: ANNO 4 | T42: ANNO 5 | X42: O/P
C43: 4 FSDJ | D43: SEM 1 | F43: SEM 2 | H43: SEM 1 | J43: SEM 2 | L43: SEM 1 | N43: SEM 2 | P43: SEM 1 | R43: SEM 2 | T43: SEM 1 | V43: SEM 2 | X43: ANNO 1 | Y43: ANNO 2 | Z43: ANNO 3 | AA43: ANNO 4 | AB43: ANNO 5 | AC43: TOTALE
C44: A. Promozione Piattaforma e Assistenza Commerciale | D44: 0 | E44: 0 | F44: 0 | G44: 0 | H44: 0 | I44: 0 | J44: 0 | K44: 0 | L44: 0 | M44: 0 | N44: 0 | O44: 0 | P44: 0 | Q44: 0 | R44: 0 | S44: 0 | T44: 0 | U44: 0 | V44: 0 | W44: 0 | X44: =SUM(D44:G44)*$B$12 -> 0 | Y44: =SUM(H44:K44)*$B$12 -> 0 | Z44: =SUM(L44:O44)*$B$12 -> 0 | AA44: =SUM(P44:S44)*$B$12 -> 0 | AB44: =SUM(T44:W44)*$B$12 -> 0 | AC44: =SUM(X44:AB44) -> 0
C45: B. Manutenzione Ordinaria | D45: 1.8 | E45: 1.8 | F45: 1.8 | G45: 1.8 | H45: 1.8 | I45: 1.8 | J45: 1.8 | K45: 1.8 | L45: 0.8 | M45: 0.8 | N45: 0.8 | O45: 0.8 | P45: 0.8 | Q45: 0.8 | R45: 0.8 | S45: 0.8 | T45: 0.8 | U45: 0.8 | V45: 0.8 | W45: 0.8 | X45: =SUM(D45:G45)*$B$12 -> 3153.6 | Y45: =SUM(H45:K45)*$B$12 -> 3153.6 | Z45: =SUM(L45:O45)*$B$12 -> 1401.6 | AA45: =SUM(P45:S45)*$B$12 -> 1401.6 | AB45: =SUM(T45:W45)*$B$12 -> 1401.6 | AC45: =SUM(X45:AB45) -> 10512
C46: C. Manutenzione Evolutiva | L46: 1.4 | M46: 1.4 | N46: 1.4 | O46: 1.4 | P46: 1.4 | Q46: 1.4 | R46: 1.4 | S46: 1.4 | T46: 1.4 | U46: 1.4 | V46: 1.4 | W46: 1.4 | X46: =SUM(D46:G46)*$B$12 -> 0 | Y46: =SUM(H46:K46)*$B$12 -> 0 | Z46: =SUM(L46:O46)*$B$12 -> 2452.8 | AA46: =SUM(P46:S46)*$B$12 -> 2452.8 | AB46: =SUM(T46:W46)*$B$12 -> 2452.8 | AC46: =SUM(X46:AB46) -> 7358.4
C47: D. Assistenza Intermediari | D47: 1.2 | E47: 1.2 | F47: 1.2 | G47: 1.2 | H47: 1.2 | I47: 1.2 | J47: 1.2 | K47: 1.2 | L47: 0.8 | M47: 0.8 | N47: 0.8 | O47: 0.8 | P47: 0.8 | Q47: 0.8 | R47: 0.8 | S47: 0.8 | T47: 0.8 | U47: 0.8 | V47: 0.8 | W47: 0.8 | X47: =SUM(D47:G47)*$B$12 -> 2102.4 | Y47: =SUM(H47:K47)*$B$12 -> 2102.4 | Z47: =SUM(L47:O47)*$B$12 -> 1401.6 | AA47: =SUM(P47:S47)*$B$12 -> 1401.6 | AB47: =SUM(T47:W47)*$B$12 -> 1401.6 | AC47: =SUM(X47:AB47) -> 8409.6
C48: E. Analisi di Dati di Esercizio della piattaforma | D48: 1 | E48: 1 | F48: 1 | G48: 1 | H48: 1 | I48: 1 | J48: 1 | K48: 1 | L48: 1 | M48: 1 | N48: 1 | O48: 1 | P48: 1 | Q48: 1 | R48: 1 | S48: 1 | T48: 1 | U48: 1 | V48: 1 | W48: 1 | X48: =SUM(D48:G48)*$B$12 -> 1752 | Y48: =SUM(H48:K48)*$B$12 -> 1752 | Z48: =SUM(L48:O48)*$B$12 -> 1752 | AA48: =SUM(P48:S48)*$B$12 -> 1752 | AB48: =SUM(T48:W48)*$B$12 -> 1752 | AC48: =SUM(X48:AB48) -> 8760
...

Sheet Gruppi Fase 2
F2: ANNO 1 | H2: ANNO 2 | J2: ANNO 3 | L2: ANNO 4 | N2: ANNO 5 | P2: TOTALE
B3: Gruppo | C3: Num Persone | D3: Tipologia | E3: Tasks | F3: O/P | G3: A/P | H3: O/P | I3: A/P | J3: O/P | K3: A/P | L3: O/P | M3: A/P | N3: O/P | O3: A/P | P3: O/P | Q3: A/P
B4: 4 | C4: 8 | D4: 0,5 PM 0,5 SA 2 FSD 4 FSDJ | E4: A. Promozione Piattaforma e Assistenza Commerciale B. Manutenzione Ordinaria C. Manutenzione Evolutiva D. Assistenza Intermediari E. Analisi di Dati di Esercizio della piattaforma | F4: ='Plan Fase 2'!X58 -> 12264 | G4: =F4/'Plan Fase 1'!$B$34 -> 7 | H4: ='Plan Fase 2'!Y58 -> 12264 | I4: =H4/'Plan Fase 1'!$B$34 -> 7 | J4: ='Plan Fase 2'!Z58 -> 12264 | K4: =J4/'Plan Fase 1'!$B$34 -> 7 | L4: ='Plan Fase 2'!AA58 -> 12264 | M4: =L4/'Plan Fase 1'!$B$34 -> 7 | N4: ='Plan Fase 2'!AB58 -> 12264 | O4: =N4/'Plan Fase 1'!$B$34 -> 7 | P4: =F4+H4+J4+L4+N4 -> 61320 | Q4: =P4/'Plan Fase 1'!$B$34 -> 35

Sheet Riepilogo Impegni OP
B5: Numero Ore per Anno | C5: ='Plan Fase 1'!B34 -> 1752
C7: NUMERO ORE
B8: Figura Professionale | C8: Anno 0 | D8: Anno 1 | E8: Anno 2 | F8: Anno 3 | G8: Anno 4 | H8: Anno 5 | I8: Totale O/P
B9: PM | C9: ='Plan Fase 1'!AB67 -> 1752 | D9: ='Plan Fase 2'!X22 -> 876 | E9: ='Plan Fase 2'!Y22 -> 876 | F9: ='Plan Fase 2'!Z22 -> 876 | G9: ='Plan Fase 2'!AA22 -> 876 | H9: ='Plan Fase 2'!AB22 -> 876 | I9: =SUM(C9:H9) -> 6132
B10: SA | C10: ='Plan Fase 1'!AB98 -> 1752 | D10: ='Plan Fase 2'!X31 -> 876 | E10: ='Plan Fase 2'!Y31 -> 876 | F10: ='Plan Fase 2'!Z31 -> 876 | G10: ='Plan Fase 2'!AA31 -> 876 | H10: ='Plan Fase 2'!AB31 -> 876 | I10: =SUM(C10:H10) -> 6132
B11: FSD | C11: ='Plan Fase 1'!AB129 -> 7008 | D11: ='Plan Fase 2'!X40 -> 3504 | E11: ='Plan Fase 2'!Y40 -> 3504 | F11: ='Plan Fase 2'!Z40 -> 3504 | G11: ='Plan Fase 2'!AA40 -> 3504 | H11: ='Plan Fase 2'!AB40 -> 3504 | I11: =SUM(C11:H11) -> 24528
B12: FSDJ | C12: ='Plan Fase 1'!AB161 -> 13432 | D12: ='Plan Fase 2'!X49 -> 7008 | E12: ='Plan Fase 2'!Y49 -> 7008 | F12: ='Plan Fase 2'!Z49 -> 7008 | G12: ='Plan Fase 2'!AA49 -> 7008 | H12: ='Plan Fase 2'!AB49 -> 7008 | I12: =SUM(C12:H12) -> 48472
B13: TOTALE O/P | C13: =SUM(C9:C12) -> 23944 | D13: =SUM(D9:D12) -> 12264 | E13: =SUM(E9:E12) -> 12264 | F13: =SUM(F9:F12) -> 12264 | G13: =SUM(G9:G12) -> 12264 | H13: =SUM(H9:H12) -> 12264 | I13: =SUM(C13:H13) -> 85264

Sheet Riepilogo Impegni AP
B5: Numero Ore per Anno | C5: 1752
C7: ANNI PERSONA (A/P)
B8: Figura Professionale | C8: Anno 0 | D8: Anno 1 | E8: Anno 2 | F8: Anno 3 | G8: Anno 4 | H8: Anno 5 | I8: Totale A/P
B9: PM | C9: ='Riepilogo Impegni OP'!C9/'Riepilogo Impegni OP'!$C$5 -> 1 | D9: ='Riepilogo Impegni OP'!D9/'Riepilogo Impegni OP'!$C$5 -> 0.5 | E9: ='Riepilogo Impegni OP'!E9/'Riepilogo Impegni OP'!$C$5 -> 0.5 | F9: ='Riepilogo Impegni OP'!F9/'Riepilogo Impegni OP'!$C$5 -> 0.5 | G9: ='Riepilogo Impegni OP'!G9/'Riepilogo Impegni OP'!$C$5 -> 0.5 | H9: ='Riepilogo Impegni OP'!H9/'Riepilogo Impegni OP'!$C$5 -> 0.5 | I9: =SUM(C9:H9) -> 3.5
B10: SA | C10: ='Riepilogo Impegni OP'!C10/'Riepilogo Impegni OP'!$C$5 -> 1 | D10: ='Riepilogo Impegni OP'!D10/'Riepilogo Impegni OP'!$C$5 -> 0.5 | E10: ='Riepilogo Impegni OP'!E10/'Riepilogo Impegni OP'!$C$5 -> 0.5 | F10: ='Riepilogo Impegni OP'!F10/'Riepilogo Impegni OP'!$C$5 -> 0.5 | G10: ='Riepilogo Impegni OP'!G10/'Riepilogo Impegni OP'!$C$5 -> 0.5 | H10: ='Riepilogo Impegni OP'!H10/'Riepilogo Impegni OP'!$C$5 -> 0.5 | I10: =SUM(C10:H10) -> 3.5
B11: FSD | C11: ='Riepilogo Impegni OP'!C11/'Riepilogo Impegni OP'!$C$5 -> 4 | D11: ='Riepilogo Impegni OP'!D11/'Riepilogo Impegni OP'!$C$5 -> 2 | E11: ='Riepilogo Impegni OP'!E11/'Riepilogo Impegni OP'!$C$5 -> 2 | F11: ='Riepilogo Impegni OP'!F11/'Riepilogo Impegni OP'!$C$5 -> 2 | G11: ='Riepilogo Impegni OP'!G11/'Riepilogo Impegni OP'!$C$5 -> 2 | H11: ='Riepilogo Impegni OP'!H11/'Riepilogo Impegni OP'!$C$5 -> 2 | I11: =SUM(C11:H11) -> 14
B12: FSDJ | C12: ='Riepilogo Impegni OP'!C12/'Riepilogo Impegni OP'!$C$5 -> 7.6666667 | D12: ='Riepilogo Impegni OP'!D12/'Riepilogo Impegni OP'!$C$5 -> 4 | E12: ='Riepilogo Impegni OP'!E12/'Riepilogo Impegni OP'!$C$5 -> 4 | F12: ='Riepilogo Impegni OP'!F12/'Riepilogo Impegni OP'!$C$5 -> 4 | G12: ='Riepilogo Impegni OP'!G12/'Riepilogo Impegni OP'!$C$5 -> 4 | H12: ='Riepilogo Impegni OP'!H12/'Riepilogo Impegni OP'!$C$5 -> 4 | I12: =SUM(C12:H12) -> 27.666667
B13: TOTALE A/P | C13: =SUM(C9:C12) -> 13.666667 | D13: =SUM(D9:D12) -> 7 | E13: =SUM(E9:E12) -> 7 | F13: =SUM(F9:F12) -> 7 | G13: =SUM(G9:G12) -> 7 | H13: =SUM(H9:H12) -> 7 | I13: =SUM(C13:H13) -> 48.666667
B14: NUMERO PERSONE | C14: 14 | D14: 8 | E14: 8 | F14: 8 | G14: 8 | H14: 8

Sheet Costi Base
B2: CALCOLO COSTO LORDO AZIENDALE PERSONALE | C2: PM | D2: SA | E2: FSD | F2: FSDJ
B3: A RAL (Retribuzione Annua Lorda) | C3: =(2493.21+1000)*13 -> 45411.73 | D3: =(2434.88+500)*13 -> 38153.44 | E3: =(2181+200)*13 -> 30953 | F3: =2032.93*13 -> 26428.09
B4: B TFR (Trattamento di fine rapporto) | C4: =C3/13.5 -> 3363.8319 | D4: =D3/13.5 -> 2826.1807 | E4: =E3/13.5 -> 2292.8148 | F4: =F3/13.5 -> 1957.6363
B5: C Oneri a carico azienda (INPS e INAIL) | C5: =C3*0.36*2/3 -> 10898.815 | D5: =D3*0.36*2/3 -> 9156.8256 | E5: =E3*0.36*2/3 -> 7428.72 | F5: =F3*0.36*2/3 -> 6342.7416
B6: D COSTO ANNUO AZIENDA = A+B+C | C6: =C3+C4+C5 -> 59674.377 | D6: =D3+D4+D5 -> 50136.446 | E6: =E3+E4+E5 -> 40674.535 | F6: =F3+F4+F5 -> 34728.468
B8: SPESE GENERALI | C8: 0.2 | D8: del costo del personale
B10: CLOUD COMPUTING | C10: PM | D10: SA | E10: FSD | F10: FSDJ
B11: COSTO ANNUO PER PERSONA | C11: =20*12+2*500 -> 1240 | D11: =20*12+2*1000 -> 2240 | E11: =20*12+2*1200 -> 2640 | F11: =20*12+2*1200 -> 2640 | G11: 20€ x mese + 2€ x numero annuo di ore utilizzo
B13: ONERI FINANZIARI | C13: 0.12 | D13: del finanziato
B15: % Tassa IRES | C15: 0.24
B16: % IRAP Calabria | C16: 0.0482

Sheet Costi Anno 0
B3: FASE 1 | C3: COSTO
B4: P: Costi Personale | C4: ='Riepilogo Impegni AP'!C9*'Costi Base'!C6+'Riepilogo Impegni AP'!C10*'Costi Base'!D6+'Riepilogo Impegni AP'!C11*'Costi Base'!E6+'Riepilogo Impegni AP'!C12*'Costi Base'!F6 -> 538760.55
B5: SG (20% P) | C5: ='Costi Base'!C8*'Costi Anno 0'!C4 -> 107752.11
B6: Costi di Cloud | C6: ='Riepilogo Impegni AP'!C9*'Costi Base'!C11+'Riepilogo Impegni AP'!C10*'Costi Base'!D11+'Riepilogo Impegni AP'!C11*'Costi Base'!E11+'Riepilogo Impegni AP'!C12*'Costi Base'!F11 -> 34280
B7: Esperti Dominio | C7: 20000
B8: C :COSTO TOTALE | C8: =SUM(C4:C7) -> 700792.66
B9: O: ONERI FINANZIARI PER C | C9: ='Costi Base'!C13*C8 -> 84095.119 | D9: per anno zero
B10: CO: COSTO CON ONERI C+O | C10: =C8+C9 -> 784887.78
B11: OF2: ONERI FINANZIARI PER CO | C11: ='Costi Base'!C$13*C10 -> 94186.533 | D11: per anno 1
B12: RATA AMMORTAMENTO | C12: =C10/5 -> 156977.56 | D12: per anni 1-5

Sheet Costi Anni 1-5
B3: COSTI FASE 2 | C3: Anno 1 | D3: Anno 2 | E3: Anno 3 | F3: Anno 4 | G3: Anno 5 | H3: TOTALE
B4: P: Personale | C4: ='Riepilogo Impegni AP'!D9*'Costi Base'!$C6+'Riepilogo Impegni AP'!D10*'Costi Base'!$D6+'Riepilogo Impegni AP'!D11*'Costi Base'!$E6+'Riepilogo Impegni AP'!D12*'Costi Base'!$F6 -> 275168.35 | D4: ='Riepilogo Impegni AP'!E9*'Costi Base'!$C6+'Riepilogo Impegni AP'!E10*'Costi Base'!$D6+'Riepilogo Impegni AP'!E11*'Costi Base'!$E6+'Riepilogo Impegni AP'!E12*'Costi Base'!$F6 -> 275168.35 | E4: ='Riepilogo Impegni AP'!F9*'Costi Base'!$C6+'Riepilogo Impegni AP'!F10*'Costi Base'!$D6+'Riepilogo Impegni AP'!F11*'Costi Base'!$E6+'Riepilogo Impegni AP'!F12*'Costi Base'!$F6 -> 275168.35 | F4: ='Riepilogo Impegni AP'!G9*'Costi Base'!$C6+'Riepilogo Impegni AP'!G10*'Costi Base'!$D6+'Riepilogo Impegni AP'!G11*'Costi Base'!$E6+'Riepilogo Impegni AP'!G12*'Costi Base'!$F6 -> 275168.35 | G4: ='Riepilogo Impegni AP'!H9*'Costi Base'!$C6+'Riepilogo Impegni AP'!H10*'Costi Base'!$D6+'Riepilogo Impegni AP'!H11*'Costi Base'!$E6+'Riepilogo Impegni AP'!H12*'Costi Base'!$F6 -> 275168.35 | H4: =SUM(C4:G4) -> 1375841.8
B5: SG (20% P) | C5: ='Costi Base'!$C8*'Costi Anni 1-5'!C4 -> 55033.671 | D5: ='Costi Base'!$C8*'Costi Anni 1-5'!D4 -> 55033.671 | E5: ='Costi Base'!$C8*'Costi Anni 1-5'!E4 -> 55033.671 | F5: ='Costi Base'!$C8*'Costi Anni 1-5'!F4 -> 55033.671 | G5: ='Costi Base'!$C8*'Costi Anni 1-5'!G4 -> 55033.671 | H5: =SUM(C5:G5) -> 275168.35
B6: Cloud per Esercizio | C6: ='Riepilogo Impegni AP'!D9*'Costi Base'!$C11+'Riepilogo Impegni AP'!D10*'Costi Base'!$D11+'Riepilogo Impegni AP'!D11*'Costi Base'!$E11+'Riepilogo Impegni AP'!D12*'Costi Base'!$F11 -> 17580 | D6: ='Riepilogo Impegni AP'!E9*'Costi Base'!$C11+'Riepilogo Impegni AP'!E10*'Costi Base'!$D11+'Riepilogo Impegni AP'!E11*'Costi Base'!$E11+'Riepilogo Impegni AP'!E12*'Costi Base'!$F11 -> 17580 | E6: ='Riepilogo Impegni AP'!F9*'Costi Base'!$C11+'Riepilogo Impegni AP'!F10*'Costi Base'!$D11+'Riepilogo Impegni AP'!F11*'Costi Base'!$E11+'Riepilogo Impegni AP'!F12*'Costi Base'!$F11 -> 17580 | F6: ='Riepilogo Impegni AP'!G9*'Costi Base'!$C11+'Riepilogo Impegni AP'!G10*'Costi Base'!$D11+'Riepilogo Impegni AP'!G11*'Costi Base'!$E11+'Riepilogo Impegni AP'!G12*'Costi Base'!$F11 -> 17580 | G6: ='Riepilogo Impegni AP'!H9*'Costi Base'!$C11+'Riepilogo Impegni AP'!H10*'Costi Base'!$D11+'Riepilogo Impegni AP'!H11*'Costi Base'!$E11+'Riepilogo Impegni AP'!H12*'Costi Base'!$F11 -> 17580 | H6: =SUM(C6:G6) -> 87900
B7: Altri Costi | C7: 15000 | D7: 12000 | E7: 10000 | F7: 8000 | G7: 8000 | H7: =SUM(C7:G7) -> 53000
B8: Ammortamento Piattaforma | C8: ='Costi Anno 0'!$C12 -> 156977.56 | D8: ='Costi Anno 0'!$C12 -> 156977.56 | E8: ='Costi Anno 0'!$C12 -> 156977.56 | F8: ='Costi Anno 0'!$C12 -> 156977.56 | G8: ='Costi Anno 0'!$C12 -> 156977.56 | H8: =SUM(C8:G8) -> 784887.78
B9: COSTO TOTALE | C9: =SUM(C4:C8) -> 519759.58 | D9: =SUM(D4:D8) -> 516759.58 | E9: =SUM(E4:E8) -> 514759.58 | F9: =SUM(F4:F8) -> 512759.58 | G9: =SUM(G4:G8) -> 512759.58 | H9: =SUM(H4:H8) -> 2576797.9
C10: Anno 1 | D10: Anno 2 | E10: Anno 3 | F10: Anno 4 | G10: Anno 5 | H10: TOTALE
B11: ONERI FINANZIARI PIATT. | C11: ='Costi Anno 0'!C11 -> 94186.533 | D11: =C11-$C13 -> 75349.227 | E11: =D11-$C13 -> 56511.92 | F11: =E11-$C13 -> 37674.613 | G11: =F11-$C13 -> 18837.307 | H11: =SUM(C11:G11) -> 282559.6
B13: Decremento Annuo Oneri | C13: ='Costi Base'!C13*'Costi Anno 0'!$C12 -> 18837.307

Sheet Ricavi Anni 1-5
B3: RICAVI FASE 2 | C3: Anno 1 | D3: Anno 2 | E3: Anno 3 | F3: Anno 4 | G3: Anno 5 | H3: TOTALE
B4: Abbonamento Annuo | C4: 35000 | D4: 35000 | E4: 35000 | F4: 35000 | G4: 35000
B5: Numero Intermediari | C5: 10 | D5: 15 | E5: 22 | F5: 30 | G5: 35 | H5: =SUM(C5:G5) -> 112
B6: Totale Abbonamenti | C6: =C4*C5 -> 350000 | D6: =D4*D5 -> 525000 | E6: =E4*E5 -> 770000 | F6: =F4*F5 -> 1050000 | G6: =G4*G5 -> 1225000 | H6: =SUM(C6:G6) -> 3920000
B7: Prezzo Verticalizzazione | C7: 4000 | D7: 4000 | E7: 3000 | F7: 3000 | G7: 3000
B8: Numero Verticalizzazioni | C8: 15 | D8: 30 | E8: 45 | F8: 68 | G8: 80 | H8: =SUM(C8:G8) -> 238
B9: Totale Verticalizzazioni | C9: =C7*C8 -> 60000 | D9: =D7*D8 -> 120000 | E9: =E7*E8 -> 135000 | F9: =F7*F8 -> 204000 | G9: =G7*G8 -> 240000 | H9: =SUM(C9:G9) -> 759000
B10: RICAVO TOTALE | C10: =C6+C9 -> 410000 | D10: =D6+D9 -> 645000 | E10: =E6+E9 -> 905000 | F10: =F6+F9 -> 1254000 | G10: =G6+G9 -> 1465000 | H10: =H6+H9 -> 4679000

Sheet Costi Ricavi
C2: Anno 1 | D2: Anno 2 | E2: Anno 3 | F2: Anno 4 | G2: Anno 5 | H2: TOTALE
B3: A - RICAVI | C3: ='Ricavi Anni 1-5'!C10 -> 410000 | D3: ='Ricavi Anni 1-5'!D10 -> 645000 | E3: ='Ricavi Anni 1-5'!E10 -> 905000 | F3: ='Ricavi Anni 1-5'!F10 -> 1254000 | G3: ='Ricavi Anni 1-5'!G10 -> 1465000 | H3: =SUM(C3:G3) -> 4679000 | J3: =(G3-C3)/C3 -> 2.5731707
B4: B - COSTI | C4: ='Costi Anni 1-5'!C9 -> 519759.58 | D4: ='Costi Anni 1-5'!D9 -> 516759.58 | E4: ='Costi Anni 1-5'!E9 -> 514759.58 | F4: ='Costi Anni 1-5'!F9 -> 512759.58 | G4: ='Costi Anni 1-5'!G9 -> 512759.58 | H4: =SUM(C4:G4) -> 2576797.9 | J4: =(G4-C4)/C4 -> -0.013467765
B5: C - ONERI FINANZIARI PIATT | C5: ='Costi Anni 1-5'!C11+MAX((C4-'Costi Anni 1-5'!C8)*'Costi Base'!$C$13,0) -> 137720.38 | D5: ='Costi Anni 1-5'!D11+MAX((D4-'Costi Anni 1-5'!D8)*'Costi Base'!$C$13,0) -> 118523.07 | E5: ='Costi Anni 1-5'!E11+MAX((E4-'Costi Anni 1-5'!E8)*'Costi Base'!$C$13,0) -> 99445.763 | F5: ='Costi Anni 1-5'!F11+MAX((F4-'Costi Anni 1-5'!F8)*'Costi Base'!$C$13,0) -> 80368.456 | G5: ='Costi Anni 1-5'!G11+MAX((G4-'Costi Anni 1-5'!G8)*'Costi Base'!$C$13,0) -> 61531.15 | H5: =SUM(C5:G5) -> 497588.81 | J5: =(G5-C5)/C5 -> -0.55321681
B6: BC - COSTI TOTALI | C6: =C4+C5 -> 657479.96 | D6: =D4+D5 -> 635282.65 | E6: =E4+E5 -> 614205.34 | F6: =F4+F5 -> 593128.04 | G6: =G4+G5 -> 574290.73 | H6: =SUM(C6:G6) -> 3074386.7 | J6: =(G6-C6)/C6 -> -0.1265274
B7: R1 - Risultato Lordo A-BC | C7: =C3-C6 -> -247479.96 | D7: =D3-D6 -> 9717.3511 | E7: =E3-E6 -> 290794.66 | F7: =F3-F6 -> 660871.96 | G7: =G3-G6 -> 890709.27 | H7: =SUM(C7:G7) -> 1604613.3 | J7: =(G7-C7)/C7 -> -4.5991168
B8: % Risultato/Ricavi (R1/A) | C8: =C7/C3 -> -0.60360965 | D8: =D7/D3 -> 0.015065661 | E8: =E7/E3 -> 0.32132006 | F8: =F7/F3 -> 0.52701114 | G8: =G7/G3 -> 0.60799268 | H8: =H7/H3 -> 0.34293937 | J8: =(G8-C8)/C8 -> -2.0072614
B9: T1 - Tasse IRES 24% di R1 | C9: =MAX(0,'Costi Base'!$C15*C7) -> 0 | D9: =MAX(0,'Costi Base'!$C15*D7) -> 2332.1643 | E9: =MAX(0,'Costi Base'!$C15*E7) -> 69790.718 | F9: =MAX(0,'Costi Base'!$C15*F7) -> 158609.27 | G9: =MAX(0,'Costi Base'!$C15*G7) -> 213770.23 | H9: =SUM(C9:G9) -> 444502.38 | J9: =(G9-C9)/C9 -> #DIV/0!
B10: IR: Imponibile IRAP | C10: =C7+'Costi Anni 1-5'!C4 -> 27688.397 | D10: =D7+'Costi Anni 1-5'!D4 -> 284885.7 | E10: =E7+'Costi Anni 1-5'!E4 -> 565963.01 | F10: =F7+'Costi Anni 1-5'!F4 -> 936040.32 | G10: =G7+'Costi Anni 1-5'!G4 -> 1165877.6 | H10: =SUM(C10:G10) -> 2980455.1 | J10: =(G10-C10)/C10 -> 41.107082
B11: T2 - Tasse IRAP 4,82% di IR | C11: ='Costi Base'!$C16*C10 -> 1334.5808 | D11: ='Costi Base'!$C16*D10 -> 13731.491 | E11: ='Costi Base'!$C16*E10 -> 27279.417 | F11: ='Costi Base'!$C16*F10 -> 45117.143 | G11: ='Costi Base'!$C16*G10 -> 56195.301 | H11: =SUM(C11:G11) -> 143657.93 | J11: =(G11-C11)/C11 -> 41.107082
B12: R2 - Risultato Netto R1-T1-T2 | C12: =C7-C9-C11 -> -248814.54 | D12: =D7-D9-D11 -> -6346.3041 | E12: =E7-E9-E11 -> 193724.52 | F12: =F7-F9-F11 -> 457145.55 | G12: =G7-G9-G11 -> 620743.74 | H12: =SUM(C12:G12) -> 1016453 | J12: =(G12-C12)/C12 -> -3.494805
B13: % Risultato/Ricavi (R2/A) | C13: =C12/C3 -> -0.60686472 | D13: =D12/D3 -> -0.0098392312 | E13: =E12/E3 -> 0.21406025 | F13: =F12/F3 -> 0.36454988 | G13: =G12/G3 -> 0.42371587 | H13: =H12/H3 -> 0.21723723
B14: RC - Risultato Netto Cumulato | C14: =C12 -> -248814.54 | D14: =C14+D12 -> -255160.84 | E14: =D14+E12 -> -61436.318 | F14: =E14+F12 -> 395709.23 | G14: =F14+G12 -> 1016453
B40: Risultato Netto Cumulato | C40: =H12 -> 1016453
B41: Capitale Investito | C41: ='Costi Anno 0'!C10 -> 784887.78
B42: ROI in 5 anni | C42: =C40/C41 -> 1.2950297
B43: Annuo:(ROI-100%)/5 | C43: =(C42-1)/5 -> 0.059005938
